Workbook

Sheet Data_Source
A1: table_name | B1: id | C1: user_id | D1: email | E1: last_sign_in_at | F1: application_id | G1: outcome | H1: outcome_date | I1: from_status | J1: to_status | K1: changed_at | L1: job_id | M1: cv_id | N1: application_date | O1: current_status | P1: content | Q1: visibility | R1: description | S1: source | T1: summary | U1: skills | V1: experience | W1: recommendation_id | X1: rating | Y1: intended_action | Z1: insight_id | AA1: state | AB1: shown_at | AC1: reviewed_at | AD1: dismissed_at | AE1: created_at | AF1: updated_at | AG1: context_ready
A2: auth.users | B2: SIM-U01 | D2: sim.user01@careerpilot.test | E2: 2026-08-25T09:08:00+00:00 | AE2: 2026-07-26T09:08:00+00:00 | AF2: 2026-08-25T09:08:00+00:00 | AG2: 1
A3: auth.users | B3: SIM-U02 | D3: sim.user02@careerpilot.test | E3: 2026-08-25T09:16:00+00:00 | AE3: 2026-07-26T09:16:00+00:00 | AF3: 2026-08-25T09:16:00+00:00 | AG3: 1
A4: auth.users | B4: SIM-U03 | D4: sim.user03@careerpilot.test | E4: 2026-08-25T09:24:00+00:00 | AE4: 2026-07-26T09:24:00+00:00 | AF4: 2026-08-25T09:24:00+00:00 | AG4: 1
A5: auth.users | B5: SIM-U04 | D5: sim.user04@careerpilot.test | E5: 2026-08-25T09:32:00+00:00 | AE5: 2026-07-26T09:32:00+00:00 | AF5: 2026-08-25T09:32:00+00:00 | AG5: 1
A6: auth.users | B6: SIM-U05 | D6: sim.user05@careerpilot.test | E6: 2026-08-25T09:40:00+00:00 | AE6: 2026-07-26T09:40:00+00:00 | AF6: 2026-08-25T09:40:00+00:00 | AG6: 1
A7: auth.users | B7: SIM-U06 | D7: sim.user06@careerpilot.test | E7: 2026-08-25T09:48:00+00:00 | AE7: 2026-07-26T09:48:00+00:00 | AF7: 2026-08-25T09:48:00+00:00 | AG7: 1
A8: auth.users | B8: SIM-U07 | D8: sim.user07@careerpilot.test | E8: 2026-08-25T09:56:00+00:00 | AE8: 2026-07-26T09:56:00+00:00 | AF8: 2026-08-25T09:56:00+00:00 | AG8: 0
A9: auth.users | B9: SIM-U08 | D9: sim.user08@careerpilot.test | E9: 2026-08-25T10:04:00+00:00 | AE9: 2026-07-26T10:04:00+00:00 | AF9: 2026-08-25T10:04:00+00:00 | AG9: 0
A10: professional_profiles | B10: SIM-PROFILE-01 | C10: SIM-U01 | T10: Product-focused professional with experience in discovery and delivery. | U10: ["Product Discovery", "Agile", "Analytics"] | V10: [{"role": "Project Coordinator", "years": 2}] | AE10: 2026-08-25T10:01:00+00:00 | AF10: 2026-08-25T10:01:00+00:00
A11: professional_profiles | B11: SIM-PROFILE-02 | C11: SIM-U02 | T11: Product-focused professional with experience in discovery and delivery. | U11: ["Product Discovery", "Agile", "Analytics"] | V11: [{"role": "Project Coordinator", "years": 2}] | AE11: 2026-08-25T10:02:00+00:00 | AF11: 2026-08-25T10:02:00+00:00
A12: professional_profiles | B12: SIM-PROFILE-03 | C12: SIM-U03 | T12: Product-focused professional with experience in discovery and delivery. | U12: ["Product Discovery", "Agile", "Analytics"] | V12: [{"role": "Project Coordinator", "years": 2}] | AE12: 2026-08-25T10:03:00+00:00 | AF12: 2026-08-25T10:03:00+00:00
A13: professional_profiles | B13: SIM-PROFILE-04 | C13: SIM-U04 | T13: Product-focused professional with experience in discovery and delivery. | U13: ["Product Discovery", "Agile", "Analytics"] | V13: [{"role": "Project Coordinator", "years": 2}] | AE13: 2026-08-25T10:04:00+00:00 | AF13: 2026-08-25T10:04:00+00:00
A14: professional_profiles | B14: SIM-PROFILE-05 | C14: SIM-U05 | T14: Product-focused professional with experience in discovery and delivery. | U14: ["Product Discovery", "Agile", "Analytics"] | V14: [{"role": "Project Coordinator", "years": 2}] | AE14: 2026-08-25T10:05:00+00:00 | AF14: 2026-08-25T10:05:00+00:00
A15: cvs | B15: SIM-CV-06 | C15: SIM-U06 | P15: {"summary": "Product and project experience", "skills": ["Agile", "Analytics"], "experience": [{"role": "Coordinator"}]} | Q15: {"summary": true, "skills": true, "experience": true} | AF15: 2026-08-25T10:30:00+00:00 | AG15: 2026-08-25T10:30:00+00:00
A16: jobs | B16: SIM-J001 | C16: SIM-U01 | R16: Collaborative product role covering discovery, prioritisation, analytics, stakeholder communication, experimentation, roadmap support, user research, backlog management and cross-functional delivery. Candidates should be comfortable working with evidence and communicating trade-offs across product, design and engineering teams. | S16: LinkedIn | AF16: 2026-06-01T08:00:00+00:00 | AG16: 2026-06-01T08:00:00+00:00
A17: applications | B17: SIM-A001 | C17: SIM-U01 | L17: SIM-J001 | N17: 46174 | O17: closed | AF17: 2026-06-01T12:00:00+00:00 | AG17: 2026-06-01T12:00:00+00:00
A18: application_status_history | B18: SIM-H001-I | C18: SIM-U01 | F18: SIM-A001 | I18: applied | J18: interview | K18: 2026-06-08T12:00:00+00:00
A19: application_status_history | B19: SIM-H001-O | C19: SIM-U01 | F19: SIM-A001 | I19: interview | J19: offer | K19: 2026-06-15T12:00:00+00:00
A20: application_outcomes | B20: SIM-O001 | C20: SIM-U01 | F20: SIM-A001 | G20: offer_accepted | H20: 46209 | AE20: 2026-07-06T00:00:00+00:00 | AF20: 2026-07-06T00:00:00+00:00
A21: jobs | B21: SIM-J002 | C21: SIM-U01 | R21: Collaborative product role covering discovery, prioritisation, analytics, stakeholder communication, experimentation, roadmap support, user research, backlog management and cross-functional delivery. Candidates should be comfortable working with evidence and communicating trade-offs across product, design and engineering teams. | S21: InfoJobs | AF21: 2026-06-04T08:00:00+00:00 | AG21: 2026-06-04T08:00:00+00:00
A22: applications | B22: SIM-A002 | C22: SIM-U01 | L22: SIM-J002 | N22: 46177 | O22: interview | AF22: 2026-06-04T12:00:00+00:00 | AG22: 2026-06-04T12:00:00+00:00
A23: application_status_history | B23: SIM-H002-I | C23: SIM-U01 | F23: SIM-A002 | I23: applied | J23: interview | K23: 2026-06-11T12:00:00+00:00
A24: jobs | B24: SIM-J003 | C24: SIM-U02 | R24: Collaborative product role covering discovery, prioritisation, analytics, stakeholder communication, experimentation, roadmap support, user research, backlog management and cross-functional delivery. Candidates should be comfortable working with evidence and communicating trade-offs across product, design and engineering teams. | S24: Company Website | AF24: 2026-06-07T08:00:00+00:00 | AG24: 2026-06-07T08:00:00+00:00
A25: applications | B25: SIM-A003 | C25: SIM-U02 | L25: SIM-J003 | N25: 46180 | O25: interview | AF25: 2026-06-07T12:00:00+00:00 | AG25: 2026-06-07T12:00:00+00:00
A26: application_status_history | B26: SIM-H003-I | C26: SIM-U02 | F26: SIM-A003 | I26: applied | J26: interview | K26: 2026-06-14T12:00:00+00:00
A27: jobs | B27: SIM-J004 | C27: SIM-U02 | R27: Collaborative product role covering discovery, prioritisation, analytics, stakeholder communication, experimentation, roadmap support, user research, backlog management and cross-functional delivery. Candidates should be comfortable working with evidence and communicating trade-offs across product, design and engineering teams. | S27: Hitmarker | AF27: 2026-06-10T08:00:00+00:00 | AG27: 2026-06-10T08:00:00+00:00
A28: applications | B28: SIM-A004 | C28: SIM-U02 | L28: SIM-J004 | N28: 46183 | O28: interview | AF28: 2026-06-10T12:00:00+00:00 | AG28: 2026-06-10T12:00:00+00:00
A29: application_status_history | B29: SIM-H004-I | C29: SIM-U02 | F29: SIM-A004 | I29: applied | J29: interview | K29: 2026-06-17T12:00:00+00:00
A30: jobs | B30: SIM-J005 | C30: SIM-U03 | R30: Collaborative product role covering discovery, prioritisation, analytics, stakeholder communication, experimentation, roadmap support, user research, backlog management and cross-functional delivery. Candidates should be comfortable working with evidence and communicating trade-offs across product, design and engineering teams. | S30: LinkedIn | AF30: 2026-06-13T08:00:00+00:00 | AG30: 2026-06-13T08:00:00+00:00
A31: applications | B31: SIM-A005 | C31: SIM-U03 | L31: SIM-J005 | N31: 46186 | O31: rejected | AF31: 2026-06-13T12:00:00+00:00 | AG31: 2026-06-13T12:00:00+00:00
A32: application_outcomes | B32: SIM-O005 | C32: SIM-U03 | F32: SIM-A005 | G32: rejected | H32: 46198 | AE32: 2026-06-25T00:00:00+00:00 | AF32: 2026-06-25T00:00:00+00:00
A33: jobs | B33: SIM-J006 | C33: SIM-U03 | R33: Collaborative product role covering discovery, prioritisation, analytics, stakeholder communication, experimentation, roadmap support, user research, backlog management and cross-functional delivery. Candidates should be comfortable working with evidence and communicating trade-offs across product, design and engineering teams. | S33: InfoJobs | AF33: 2026-06-16T08:00:00+00:00 | AG33: 2026-06-16T08:00:00+00:00
A34: applications | B34: SIM-A006 | C34: SIM-U03 | L34: SIM-J006 | N34: 46189 | O34: rejected | AF34: 2026-06-16T12:00:00+00:00 | AG34: 2026-06-16T12:00:00+00:00
A35: application_outcomes | B35: SIM-O006 | C35: SIM-U03 | F35: SIM-A006 | G35: rejected | H35: 46201 | AE35: 2026-06-28T00:00:00+00:00 | AF35: 2026-06-28T00:00:00+00:00
A36: jobs | B36: SIM-J007 | C36: SIM-U04 | R36: Collaborative product role covering discovery, prioritisation, analytics, stakeholder communication, experimentation, roadmap support, user research, backlog management and cross-functional delivery. Candidates should be comfortable working with evidence and communicating trade-offs across product, design and engineering teams. | S36: Company Website | AF36: 2026-06-19T08:00:00+00:00 | AG36: 2026-06-19T08:00:00+00:00
A37: applications | B37: SIM-A007 | C37: SIM-U04 | L37: SIM-J007 | N37: 46192 | O37: rejected | AF37: 2026-06-19T12:00:00+00:00 | AG37: 2026-06-19T12:00:00+00:00
A38: application_outcomes | B38: SIM-O007 | C38: SIM-U04 | F38: SIM-A007 | G38: rejected | H38: 46204 | AE38: 2026-07-01T00:00:00+00:00 | AF38: 2026-07-01T00:00:00+00:00
A39: jobs | B39: SIM-J008 | C39: SIM-U04 | R39: Collaborative product role covering discovery, prioritisation, analytics, stakeholder communication, experimentation, roadmap support, user research, backlog management and cross-functional delivery. Candidates should be comfortable working with evidence and communicating trade-offs across product, design and engineering teams. | S39: Hitmarker | AF39: 2026-06-22T08:00:00+00:00 | AG39: 2026-06-22T08:00:00+00:00
A40: applications | B40: SIM-A008 | C40: SIM-U04 | L40: SIM-J008 | N40: 46195 | O40: rejected | AF40: 2026-06-22T12:00:00+00:00 | AG40: 2026-06-22T12:00:00+00:00
...

Sheet Dashboard
A1: CareerPilot — MVP Monitoring Dashboard | M1: SIMULATED DEMO DATA
A3: Monitoring whether users reach CareerPilot's contextual decision-support experience and perceive it as useful.
A5: Primary Product KPIs
A6: Recommendation Usefulness Rate | E6: Recommendation Review Rate | I6: Recommendation Feedback Coverage | M6: Context Readiness Rate
A7: =IFERROR($K$14/$I$14,0) -> 0.66666667 | E7: =IFERROR($G$14/$E$14,0) -> 0.625 | I7: =IFERROR($I$14/$G$14,0) -> 0.6 | M7: =IFERROR($C$14/$A$14,0) -> 0.75
A10: =TEXT($K$14,"0")&" of "&TEXT($I$14,"0")&" feedback ratings are helpful" -> 4 of 6 feedback ratings are helpful | E10: =TEXT($G$14,"0")&" of "&TEXT($E$14,"0")&" shown recommendations reviewed" -> 10 of 16 shown recommendations reviewed | I10: =TEXT($I$14,"0")&" of "&TEXT($G$14,"0")&" reviewed recommendations rated" -> 6 of 10 reviewed recommendations rated | M10: =TEXT($C$14,"0")&" of "&TEXT($A$14,"0")&" activated users are context ready" -> 6 of 8 activated users are context ready
A12: Recommendation Experience — Observed Counts
A13: Activated Users | C13: Context Ready Users | E13: Recommendations Shown | G13: Recommendations Reviewed | I13: Feedback Provided | K13: Helpful Recommendations
A14: =COUNTIFS(Data_Source!$A$2:$A60,"auth.users",Data_Source!$E$2:$E60,"<>") -> 8 | C14: =COUNTIFS(Data_Source!$A$2:$A60,"auth.users",Data_Source!$AG$2:$AG60,1) -> 6 | E14: =COUNTIFS(Data_Source!$A$2:$A60,"recommendations",Data_Source!$AB$2:$AB60,"<>") -> 16 | G14: =COUNTIFS(Data_Source!$A$2:$A60,"recommendations",Data_Source!$AC$2:$AC60,"<>") -> 10 | I14: =COUNTIFS(Data_Source!$A$2:$A60,"recommendation_feedback",Data_Source!$X$2:$X60,"helpful")+COUNTIFS(Data_Source!$A$2:$A60,"recommendation_feedback",Data_Source!$X$2:$X60,"not_helpful") -> 6 | K14: =COUNTIFS(Data_Source!$A$2:$A60,"recommendation_feedback",Data_Source!$X$2:$X60,"helpful") -> 4
A17: Recommendation Feedback | I17: Recommendation State
A32: Job-Search Outcomes — Observational
A33: Recorded Applications | E33: Interview Rate | I33: Offer Rate | M33: Accepted Offer Duration
A34: =COUNTIF(Data_Source!$A$2:$A60,"applications") -> 16 | E34: =IFERROR(COUNTIFS(Data_Source!$A$2:$A60,"application_status_history",Data_Source!$J$2:$J60,"interview")/$A$34,0) -> 0.25 | I34: =IFERROR(COUNTIFS(Data_Source!$A$2:$A60,"application_status_history",Data_Source!$J$2:$J60,"offer")/$A$34,0) -> 0.0625 | M34: =IFERROR(MINIFS(Data_Source!$H$2:$H60,Data_Source!$A$2:$A60,"application_outcomes",Data_Source!$G$2:$G60,"offer_accepted")-MINIFS(Data_Source!$N$2:$N60,Data_Source!$A$2:$A60,"applications"),0) -> 35
A37: All recorded applications | E37: =TEXT(COUNTIFS(Data_Source!$A$2:$A60,"application_status_history",Data_Source!$J$2:$J60,"interview"),"0")&" of "&TEXT($A$34,"0")&" applications reached interview" -> 4 of 16 applications reached interview | I37: =TEXT(COUNTIFS(Data_Source!$A$2:$A60,"application_status_history",Data_Source!$J$2:$J60,"offer"),"0")&" of "&TEXT($A$34,"0")&" applications reached offer" -> 1 of 16 applications reached offer | M37: Avg. days from first recorded application
A39: Jobs by Source | I39: Monitoring Narrative
I40: Review cadence — Check instrumentation after each validation session; interpret the KPI set after each validation round. Good movement — More users become context ready, review recommendations, provide enough feedback, and rate recommendations as helpful. Bad movement — Falling readiness or review, insufficient feedback coverage, or lower usefulness signals friction or weak recommendation value. Decision — Strong usefulness with sufficient coverage supports Continue / Strengthen. High review but low usefulness triggers recommendation-quality/context iteration; low review with healthy readiness triggers presentation/relevance iteration; low readiness triggers setup/context simplification. Hiring outcomes remain observational. | Q40: rating | R40: recommendations
Q41: helpful | R41: =COUNTIFS(Data_Source!$A$2:$A60,"recommendation_feedback",Data_Source!$X$2:$X60,"helpful") -> 4
Q42: not_helpful | R42: =COUNTIFS(Data_Source!$A$2:$A60,"recommendation_feedback",Data_Source!$X$2:$X60,"not_helpful") -> 2
Q45: state | R45: recommendations
Q46: active | R46: =COUNTIFS(Data_Source!$A$2:$A60,"recommendations",Data_Source!$AA$2:$AA60,"active") -> 13
I47: SIMULATED DEMO DATA — fallback data for presentation and dashboard testing. Replace the rows in Data_Source with equivalent real Lovable/Supabase exports when available; the dashboard formulas will update automatically. | Q47: dismissed | R47: =COUNTIFS(Data_Source!$A$2:$A60,"recommendations",Data_Source!$AA$2:$AA60,"dismissed") -> 3
Q50: source | R50: jobs
Q51: LinkedIn | R51: =COUNTIFS(Data_Source!$A$2:$A60,"jobs",Data_Source!$S$2:$S60,Q51) -> 4
Q52: InfoJobs | R52: =COUNTIFS(Data_Source!$A$2:$A60,"jobs",Data_Source!$S$2:$S60,Q52) -> 4
Q53: Company Website | R53: =COUNTIFS(Data_Source!$A$2:$A60,"jobs",Data_Source!$S$2:$S60,Q53) -> 4
Q54: Hitmarker | R54: =COUNTIFS(Data_Source!$A$2:$A60,"jobs",Data_Source!$S$2:$S60,Q54) -> 4
